<?xml version="1.0" ?>
<sdf version="1.5">
  <model name="differential_car">
    <pose>0 0 0 0 0 0</pose>

    <link name="base_link">
      <inertial>
        <mass>10</mass>
        <inertia>
          <ixx>0.1</ixx>
          <ixy>0</ixy>
          <ixz>0</ixz>
          <iyy>0.1</iyy>
          <iyz>0</iyz>
          <izz>0.1</izz>
        </inertia>
      </inertial>

      <collision name="base_collision">
        <geometry>
          <box>
            <size>1 0.5 0.2</size>
          </box>
        </geometry>
      </collision>

      <visual name="base_visual">
        <geometry>
          <box>
            <size>1 0.5 0.2</size>
          </box>
        </geometry>

        <material>
          <script>
            <uri>file://media/materials/scripts/gazebo.material</uri>
            <name>Gazebo/Blue</name>
          </script>
        </material>
      </visual>
    </link>

    <link name="left_wheel">
      <inertial>
        <mass>1</mass>
        <inertia>
          <ixx>0.005</ixx>
          <ixy>0</ixy>
          <ixz>0</ixz>
          <iyy>0.005</iyy>
          <iyz>0</iyz>
          <izz>0.005</izz>
        </inertia>
      </inertial>

      <collision name="left_wheel_collision">
        <geometry>
          <cylinder>
            <radius>0.1</radius>
            <length>0.05</length>
          </cylinder>
        </geometry>

        <surface>
          <friction>
            <ode>
              <mu>0.2</mu>
              <mu2>0.1</mu2>
            </ode>
          </friction>
        </surface>
      </collision>

      <visual name="left_wheel_visual">
        <geometry>
          <cylinder>
            <radius>0.1</radius>
            <length>0.05</length>
          </cylinder>
        </geometry>

        <material>
          <script>
            <uri>file://media/materials/scripts/gazebo.material</uri>
            <name>Gazebo/Blue</name>
          </script>
        </material>
      </visual>
    </link>

    <link name="right_wheel">
      <inertial>
        <mass>1</mass>
        <inertia>
          <ixx>0.005</ixx>
          <ixy>0</ixy>
          <ixz>0</ixz>
          <iyy>0.005</iyy>
          <iyz>0</iyz>
          <izz>0.005</izz>
        </inertia>
      </inertial>

      <collision name="right_wheel_collision">
        <geometry>
          <cylinder>
            <radius>0.1</radius>
            <length>0.05</length>
          </cylinder>
        </geometry>

        <surface>
          <friction>
            <ode>
              <mu>0.2</mu>
              <mu2>0.1</mu2>
            </ode>
          </friction>
        </surface>
      </collision>

      <visual name="right_wheel_visual">
        <geometry>
          <cylinder>
            <radius>0.1</radius>
            <length>0.05</length>
          </cylinder>
        </geometry>

        <material>
          <script>
            <uri>file://media/materials/scripts/gazebo.material</uri>
            <name>Gazebo/Blue</name>
          </script>
        </material>
      </visual>
    </link>

    <joint name="left_wheel_joint" type="revolute">
      <parent>base_link</parent>
      <child>left_wheel</child>
      <axis>
        <xyz>0 0 1</xyz>
        <limit>
          <lower>-3.14</lower>
          <upper>3.14</upper>
          <effort>10</effort>
          <velocity>1</velocity>
        </limit>
      </axis>
      <physics>
        <ode>
          <damping>1</damping>
          <friction>0</friction>
        </ode>
      </physics>
    </joint>

    <joint name="right_wheel_joint" type="revolute">
      <parent>base_link</parent>
      <child>right_wheel</child>
      <axis>
        <xyz>0 0 1</xyz>
        <limit>
          <lower>-3.14</lower>
          <upper>3.14</upper>
          <effort>10</effort>
          <velocity>1</velocity>
        </limit>
      </axis>
      <physics>
        <ode>
          <damping>1</damping>
          <friction>0</friction>
        </ode>
      </physics>
    </joint>
  </model>
</sdf>
