<?xml version="1.0" ?>
<sdf version="1.6">
  <model name="my_car">
    <link name="chassis">
      <pose>0 0 0.1 0 0 0</pose>
      <collision name="collision">
        <geometry>
          <box>
            <size>1.0 0.5 0.2</size>
          </box>
        </geometry>
      </collision>
      <visual name="visual">
        <geometry>
          <box>
            <size>1.0 0.5 0.2</size>
          </box>
        </geometry>
        <material>
          <script>
            <uri>file://media/materials/scripts/gazebo.material</uri>
            <name>Gazebo/Red</name>
          </script>
        </material>
      </visual>
    </link>

    <joint name="front_left_wheel_joint" type="revolute">
      <parent>chassis</parent>
      <child>front_left_wheel</child>
      <axis>
        <xyz>0 1 0</xyz>
        <limit>
          <lower>-1.0</lower>
          <upper>1.0</upper>
          <effort>10.0</effort>
          <velocity>5.0</velocity>
        </limit>
      </axis>
      <physics>
        <ode>
          <damping>10.0</damping>
          <friction>2.0</friction>
        </ode>
      </physics>
    </joint>

    <link name="front_left_wheel">
      <pose>0.3 -0.28 0.05 0 1.5 1.5</pose>
      <collision name="collision">
        <geometry>
          <cylinder>
            <radius>0.09</radius>
            <length>0.05</length>
          </cylinder>
        </geometry>
      </collision>
      <visual name="visual">
        <geometry>
          <cylinder>
            <radius>0.09</radius>
            <length>0.05</length>
          </cylinder>
        </geometry>
        <material>
          <script>
            <uri>file://media/materials/scripts/gazebo.material</uri>
            <name>Gazebo/Blue</name>
          </script>
        </material>
      </visual>
      <inertial>
        <mass>0.1</mass>
        <inertia>
          <ixx>0.0001</ixx>
          <iyy>0.0001</iyy>
          <izz>0.0001</izz>
        </inertia>
      </inertial>
    </link>

    <joint name="front_right_wheel_joint" type="revolute">
      <parent>chassis</parent>
      <child>front_right_wheel</child>
      <axis>
        <xyz>0 -1 0</xyz>
        <limit>
          <lower>-1.0</lower>
          <upper>1.0</upper>
          <effort>10.0</effort>
          <velocity>5.0</velocity>
        </limit>
      </axis>
      <physics>
        <ode>
          <damping>10.0</damping>
          <friction>2.0</friction>
        </ode>
      </physics>
    </joint>

    <link name="front_right_wheel">
      <pose>0.3 0.28 0.05 0 1.5 1.5</pose>
      <collision name="collision">
        <geometry>
          <cylinder>
            <radius>0.09</radius>
            <length>0.05</length>
          </cylinder>
        </geometry>
      </collision>
      <visual name="visual">
        <geometry>
          <cylinder>
            <radius>0.09</radius>
            <length>0.05</length>
          </cylinder>
        </geometry>
        <material>
          <script>
            <uri>file://media/materials/scripts/gazebo.material</uri>
            <name>Gazebo/Blue</name>
          </script>
        </material>
      </visual>
      <inertial>
        <mass>0.1</mass>
        <inertia>
          <ixx>0.0001</ixx>
          <iyy>0.0001</iyy>
          <izz>0.0001</izz>
        </inertia>
      </inertial>
    </link>

    <joint name="rear_left_wheel_joint" type="revolute">
      <parent>chassis</parent>
      <child>rear_left_wheel</child>
      <axis>
        <xyz>0 1 0</xyz>
        <limit>
          <lower>-1.0</lower>
          <upper>1.0</upper>
          <effort>10.0</effort>
          <velocity>5.0</velocity>
        </limit>
      </axis>
      <physics>
        <ode>
          <damping>10.0</damping>
          <friction>2.0</friction>
        </ode>
      </physics>
    </joint>

    <link name="rear_left_wheel">
      <pose>-0.3 -0.28 0.05 0 1.5 1.5</pose>
      <collision name="collision">
        <geometry>
          <cylinder>
            <radius>0.09</radius>
            <length>0.05</length>
          </cylinder>
        </geometry>
      </collision>
      <visual name="visual">
        <geometry>
          <cylinder>
            <radius>0.09</radius>
            <length>0.05</length>
          </cylinder>
        </geometry>
        <material>
          <script>
            <uri>file://media/materials/scripts/gazebo.material</uri>
            <name>Gazebo/Blue</name>
          </script>
        </material>
      </visual>
      <inertial>
        <mass>0.1</mass>
        <inertia>
          <ixx>0.0001</ixx>
          <iyy>0.0001</iyy>
          <izz>0.0001</izz>
        </inertia>
      </inertial>
    </link>

    <joint name="rear_right_wheel_joint" type="revolute">
      <parent>chassis</parent>
      <child>rear_right_wheel</child>
      <axis>
        <xyz>0 -1 0</xyz>
        <limit>
          <lower>-1.0</lower>
          <upper>1.0</upper>
          <effort>10.0</effort>
          <velocity>5.0</velocity>
        </limit>
      </axis>
      <physics>
        <ode>
          <damping>10.0</damping>
          <friction>2.0</friction>
        </ode>
      </physics>
    </joint>

    <link name="rear_right_wheel">
      <pose>-0.3 0.28 0.05 0 1.5 1.5</pose>
      <collision name="collision">
        <geometry>
          <cylinder>
            <radius>0.09</radius>
            <length>0.05</length>
          </cylinder>
        </geometry>
      </collision>
      <visual name="visual">
        <geometry>
          <cylinder>
            <radius>0.09</radius>
            <length>0.05</length>
          </cylinder>
        </geometry>
        <material>
          <script>
            <uri>file://media/materials/scripts/gazebo.material</uri>
            <name>Gazebo/Blue</name>
          </script>
        </material>
      </visual>
      <inertial>
        <mass>0.1</mass>
        <inertia>
          <ixx>0.0001</ixx>
          <iyy>0.0001</iyy>
          <izz>0.0001</izz>
        </inertia>
      </inertial>
    </link>
    <plugin
    filename="gz-sim-diff-drive-system"
    name="gz::sim::systems::DiffDrive">

    <right_joint>rear_right_wheel_joint</right_joint>
    <left_joint>rear_left_wheel_joint</left_joint>
    <right_joint>front_right_wheel_joint</right_joint>
    <left_joint>front_left_wheel_joint</left_joint> 


    <wheel_separation>.6</wheel_separation>
    <wheel_radius>0.9</wheel_radius>
    <odom_publish_frequency>1</odom_publish_frequency>
    <topic>cmd_vel</topic>
</plugin>
  </model>
</sdf>

<!-- <?xml version="1.0" ?>
<sdf version="1.6">
  <model name="my_car">
    <link name="chassis">
      <pose>0 0 0.1 0 0 0</pose>
      <collision name="collision">
        <geometry>
          <box>
            <size>0.5 0.3 0.1</size>
          </box>
        </geometry>
      </collision>
      <visual name="visual">
        <geometry>
          <box>
            <size>0.5 0.3 0.1</size>
          </box>
        </geometry>
        <material>
          <script>
            <uri>file://media/materials/scripts/gazebo.material</uri>
            <name>Gazebo/Black</name>
          </script>
        </material>
      </visual>
    </link>

    <joint name="left_wheel_joint" type="revolute">
      <parent>chassis</parent>
      <child>left_wheel</child>
      <axis>
        <xyz>0 1 0</xyz>
        <limit>
          <lower>-1.0</lower>
          <upper>1.0</upper>
          <effort>10.0</effort>
          <velocity>5.0</velocity>
        </limit>
      </axis>
    </joint>

    <link name="left_wheel">
      <pose>-0.2 0 0.05 0 0 0</pose>
      <collision name="collision">
        <!-- <geometry>
          <cylinder>
            <radius>0.05</radius>
            <length>0.1</length>
          </cylinder>
        </geometry> -->
        <geometry>
              <sphere>
              <radius>.07</radius>
            </sphere>
          </geometry>
      </collision>
      <visual name="visual">
        <!-- <geometry>
          <cylinder>
            <radius>0.05</radius>
            <length>0.1</length>
          </cylinder>
        </geometry> -->
        <geometry>
              <sphere>
              <radius>.07</radius>
            </sphere>
          </geometry>
        <material>
          <script>
            <uri>file://media/materials/scripts/gazebo.material</uri>
            <name>Gazebo/Blue</name>
          </script>
        </material>
      </visual>
      <inertial>
        <mass>0.1</mass>
        <inertia>
          <ixx>0.0001</ixx>
          <iyy>0.0001</iyy>
          <izz>0.0001</izz>
        </inertia>
      </inertial>
    </link>

    <joint name="right_wheel_joint" type="revolute">
      <parent>chassis</parent>
      <child>right_wheel</child>
      <axis>
        <xyz>0 -1 0</xyz>
        <limit>
          <lower>-1.0</lower>
          <upper>1.0</upper>
          <effort>10.0</effort>
          <velocity>5.0</velocity>
        </limit>
      </axis>
    </joint>

    <link name="right_wheel">
      <pose>0.2 0 0.05 15 0 0</pose>
      <collision name="collision">
        <!-- <geometry>
          <cylinder>
            <radius>0.05</radius>
            <length>0.05</length>
          </cylinder>
        </geometry> -->
        <geometry>
      <sphere>
        <radius>0.07</radius>
      </sphere>
    </geometry>
      </collision>
      <visual name="visual">
        <!-- <geometry>
          <cylinder>
            <radius>0.05</radius>
            <length>0.05</length>
          </cylinder>
        </geometry> -->
        <geometry>
      <sphere>
        <radius>0.07</radius>
      </sphere>
    </geometry>
        <material>
          <script>
            <uri>file://media/materials/scripts/gazebo.material</uri>
            <name>Gazebo/Red</name>
          </script>
        </material>
      </visual>
      <inertial>
        <mass>0.1</mass>
        <inertia>
          <ixx>0.0001</ixx>
          <iyy>0.0001</iyy>
          <izz>0.0001</izz>
        </inertia>
      </inertial>
    </link>
  </model>
</sdf> -->

